<?xml version="1.0" encoding="utf-8"?>
<!-- This URDF was automatically created by SolidWorks to URDF Exporter! Originally created by Stephen Brawner (brawner@gmail.com) 
     Commit Version: 1.6.0-4-g7f85cfe  Build Version: 1.6.7995.38578
     For more information, please see http://wiki.ros.org/sw_urdf_exporter -->
<robot
  name="excavator_JCB">
  <link
    name="base_link">
    <inertial>
      <origin
        xyz="0.4294466 0.0012485 0.0380234"
        rpy="0 0 0" />
      <mass
        value="1344.56" />
      <inertia
        ixx="488.8784"
        ixy="-1.551611"
        ixz="-14.97196"
        iyy="896.8346"
        iyz="-0.0436094"
        izz="1351.993" />
    </inertial>
    <visual>
      <origin
        xyz="0 0 0"
        rpy="0 0 0" />
      <geometry>
        <mesh
          filename="package://excavator_JCB/meshes/base_link.STL" />
      </geometry>
      <material
        name="">
        <color
          rgba="0.77647 0.75686 0.73725 1" />
      </material>
    </visual>
    <collision>
      <origin
        xyz="0 0 0"
        rpy="0 0 0" />
      <geometry>
        <mesh
          filename="package://excavator_JCB/meshes/base_link.STL" />
      </geometry>
    </collision>
  </link>
  <link
    name="body_yaw_link">
    <inertial>
      <origin
        xyz="0.1038247 0.0105464 0.3946706"
        rpy="0 0 0" />
      <mass
        value="6265.561" />
      <inertia
        ixx="2571.556"
        ixy="195.6274"
        ixz="69.32561"
        iyy="3687.875"
        iyz="-120.0013"
        izz="3929.211" />
    </inertial>
    <visual>
      <origin
        xyz="0 0 0"
        rpy="0 0 0" />
      <geometry>
        <mesh
          filename="package://excavator_JCB/meshes/body_yaw_link.STL" />
      </geometry>
      <material
        name="">
        <color
          rgba="0.89804 0.91765 0.92941 1" />
      </material>
    </visual>
    <collision>
      <origin
        xyz="0 0 0"
        rpy="0 0 0" />
      <geometry>
        <mesh
          filename="package://excavator_JCB/meshes/body_yaw_link.STL" />
      </geometry>
    </collision>
  </link>
  <joint
    name="body_yaw_joint"
    type="continuous">
    <origin
      xyz="0 0 0.36323"
      rpy="0 0 0" />
    <parent
      link="base_link" />
    <child
      link="body_yaw_link" />
    <axis
      xyz="0 0 1" />
  </joint>
  <link
    name="boom_pitch_link">
    <inertial>
      <origin
        xyz="0.4173408 -1.134166 -0.0415453"
        rpy="0 0 0" />
      <mass
        value="724.9529" />
      <inertia
        ixx="282.0599"
        ixy="118.3342"
        ixz="0.0157727"
        iyy="101.1092"
        iyz="-0.2015522"
        izz="371.1804" />
    </inertial>
    <visual>
      <origin
        xyz="0 0 0"
        rpy="0 0 0" />
      <geometry>
        <mesh
          filename="package://excavator_JCB/meshes/boom_pitch_link.STL" />
      </geometry>
      <material
        name="">
        <color
          rgba="0.69804 0.69804 0.69804 1" />
      </material>
    </visual>
    <collision>
      <origin
        xyz="0 0 0"
        rpy="0 0 0" />
      <geometry>
        <mesh
          filename="package://excavator_JCB/meshes/boom_pitch_link.STL" />
      </geometry>
    </collision>
  </link>
  <joint
    name="boom_pitch_joint"
    type="revolute">
    <origin
      xyz="1.5882 0.039526 0.36333"
      rpy="-1.5708 0 0" />
    <parent
      link="body_yaw_link" />
    <child
      link="boom_pitch_link" />
    <axis
      xyz="0 0 1" />
    <limit
      lower="0"
      upper="1.3703"
      effort="0"
      velocity="0" />
  </joint>
  <link
    name="forearm_pitch_link">
    <inertial>
      <origin
        xyz="0.3521181 -0.2255539 -0.328097"
        rpy="0 0 0" />
      <mass
        value="640.9527" />
      <inertia
        ixx="17.24723"
        ixy="14.701"
        ixz="-0.0567428"
        iyy="203.3294"
        iyz="-0.0303271"
        izz="211.0722" />
    </inertial>
    <visual>
      <origin
        xyz="0 0 0"
        rpy="0 0 0" />
      <geometry>
        <mesh
          filename="package://excavator_JCB/meshes/forearm_pitch_link.STL" />
      </geometry>
      <material
        name="">
        <color
          rgba="0.69804 0.69804 0.69804 1" />
      </material>
    </visual>
    <collision>
      <origin
        xyz="0 0 0"
        rpy="0 0 0" />
      <geometry>
        <mesh
          filename="package://excavator_JCB/meshes/forearm_pitch_link.STL" />
      </geometry>
    </collision>
  </link>
  <joint
    name="forearm_pitch_joint"
    type="revolute">
    <origin
      xyz="1.4233 -2.0381 0.28664"
      rpy="0 0 0" />
    <parent
      link="boom_pitch_link" />
    <child
      link="forearm_pitch_link" />
    <axis
      xyz="0 0 1" />
    <limit
      lower="0"
      upper="0.89604"
      effort="0"
      velocity="0" />
  </joint>
  <link
    name="bucket_pitch_link">
    <inertial>
      <origin
        xyz="0.1251231 -0.3655384 -0.6245874"
        rpy="0 0 0" />
      <mass
        value="652.5858" />
      <inertia
        ixx="71.85975"
        ixy="9.244171"
        ixz="0.1331334"
        iyy="143.6107"
        iyz="-0.0282737"
        izz="148.109" />
    </inertial>
    <visual>
      <origin
        xyz="0 0 0"
        rpy="0 0 0" />
      <geometry>
        <mesh
          filename="package://excavator_JCB/meshes/bucket_pitch_link.STL" />
      </geometry>
      <material
        name="">
        <color
          rgba="0.12157 0.12157 0 1" />
      </material>
    </visual>
    <collision>
      <origin
        xyz="0 0 0"
        rpy="0 0 0" />
      <geometry>
        <mesh
          filename="package://excavator_JCB/meshes/bucket_pitch_link.STL" />
      </geometry>
    </collision>
  </link>
  <joint
    name="bucket_pitch_joint"
    type="revolute">
    <origin
      xyz="1.4765 -0.24997 0.29735"
      rpy="0 0 0" />
    <parent
      link="forearm_pitch_link" />
    <child
      link="bucket_pitch_link" />
    <axis
      xyz="0 0 1" />
    <limit
      lower="0"
      upper="2.2837"
      effort="0"
      velocity="0" />
  </joint>
</robot>